2024-08-18 16:59:57,887 ERROR: Exception on /auth/login [POST] [in C:\Users\paul-\PycharmProjects\MagicWebStats\.venv\Lib\site-packages\flask\app.py:838]
Traceback (most recent call last):
  File "C:\Users\paul-\PycharmProjects\MagicWebStats\.venv\Lib\site-packages\sqlalchemy\engine\base.py", line 1967, in _exec_single_context
    self.dialect.do_execute(
  File "C:\Users\paul-\PycharmProjects\MagicWebStats\.venv\Lib\site-packages\sqlalchemy\engine\default.py", line 941, in do_execute
    cursor.execute(statement, parameters)
psycopg2.errors.UndefinedTable: FEHLER:  Relation »data_owner.user« existiert nicht
LINE 2: FROM data_owner."user" 
             ^


The above exception was the direct cause of the following exception:

Traceback (most recent call last):
  File "C:\Users\paul-\PycharmProjects\MagicWebStats\.venv\Lib\site-packages\flask\app.py", line 1473, in wsgi_app
    response = self.full_dispatch_request()
               ^^^^^^^^^^^^^^^^^^^^^^^^^^^^
  File "C:\Users\paul-\PycharmProjects\MagicWebStats\.venv\Lib\site-packages\flask\app.py", line 882, in full_dispatch_request
    rv = self.handle_user_exception(e)
         ^^^^^^^^^^^^^^^^^^^^^^^^^^^^^
  File "C:\Users\paul-\PycharmProjects\MagicWebStats\.venv\Lib\site-packages\flask\app.py", line 880, in full_dispatch_request
    rv = self.dispatch_request()
         ^^^^^^^^^^^^^^^^^^^^^^^
  File "C:\Users\paul-\PycharmProjects\MagicWebStats\.venv\Lib\site-packages\flask\app.py", line 865, in dispatch_request
    return self.ensure_sync(self.view_functions[rule.endpoint])(**view_args)  # type: ignore[no-any-return]
           ^^^^^^^^^^^^^^^^^^^^^^^^^^^^^^^^^^^^^^^^^^^^^^^^^^^^^^^^^^^^^^^^^
  File "C:\Users\paul-\PycharmProjects\MagicWebStats\app\auth\routes.py", line 19, in login
    user = db.session.scalar(
           ^^^^^^^^^^^^^^^^^^
  File "C:\Users\paul-\PycharmProjects\MagicWebStats\.venv\Lib\site-packages\sqlalchemy\orm\scoping.py", line 1843, in scalar
    return self._proxied.scalar(
           ^^^^^^^^^^^^^^^^^^^^^
  File "C:\Users\paul-\PycharmProjects\MagicWebStats\.venv\Lib\site-packages\sqlalchemy\orm\session.py", line 2410, in scalar
    return self._execute_internal(
           ^^^^^^^^^^^^^^^^^^^^^^^
  File "C:\Users\paul-\PycharmProjects\MagicWebStats\.venv\Lib\site-packages\sqlalchemy\orm\session.py", line 2247, in _execute_internal
    result: Result[Any] = compile_state_cls.orm_execute_statement(
                          ^^^^^^^^^^^^^^^^^^^^^^^^^^^^^^^^^^^^^^^^
  File "C:\Users\paul-\PycharmProjects\MagicWebStats\.venv\Lib\site-packages\sqlalchemy\orm\context.py", line 293, in orm_execute_statement
    result = conn.execute(
             ^^^^^^^^^^^^^
  File "C:\Users\paul-\PycharmProjects\MagicWebStats\.venv\Lib\site-packages\sqlalchemy\engine\base.py", line 1418, in execute
    return meth(
           ^^^^^
  File "C:\Users\paul-\PycharmProjects\MagicWebStats\.venv\Lib\site-packages\sqlalchemy\sql\elements.py", line 515, in _execute_on_connection
    return connection._execute_clauseelement(
           ^^^^^^^^^^^^^^^^^^^^^^^^^^^^^^^^^^
  File "C:\Users\paul-\PycharmProjects\MagicWebStats\.venv\Lib\site-packages\sqlalchemy\engine\base.py", line 1640, in _execute_clauseelement
    ret = self._execute_context(
          ^^^^^^^^^^^^^^^^^^^^^^
  File "C:\Users\paul-\PycharmProjects\MagicWebStats\.venv\Lib\site-packages\sqlalchemy\engine\base.py", line 1846, in _execute_context
    return self._exec_single_context(
           ^^^^^^^^^^^^^^^^^^^^^^^^^^
  File "C:\Users\paul-\PycharmProjects\MagicWebStats\.venv\Lib\site-packages\sqlalchemy\engine\base.py", line 1986, in _exec_single_context
    self._handle_dbapi_exception(
  File "C:\Users\paul-\PycharmProjects\MagicWebStats\.venv\Lib\site-packages\sqlalchemy\engine\base.py", line 2355, in _handle_dbapi_exception
    raise sqlalchemy_exception.with_traceback(exc_info[2]) from e
  File "C:\Users\paul-\PycharmProjects\MagicWebStats\.venv\Lib\site-packages\sqlalchemy\engine\base.py", line 1967, in _exec_single_context
    self.dialect.do_execute(
  File "C:\Users\paul-\PycharmProjects\MagicWebStats\.venv\Lib\site-packages\sqlalchemy\engine\default.py", line 941, in do_execute
    cursor.execute(statement, parameters)
sqlalchemy.exc.ProgrammingError: (psycopg2.errors.UndefinedTable) FEHLER:  Relation »data_owner.user« existiert nicht
LINE 2: FROM data_owner."user" 
             ^

[SQL: SELECT data_owner."user".id, data_owner."user".username, data_owner."user".email, data_owner."user".password_hash 
FROM data_owner."user" 
WHERE data_owner."user".username = %(username_1)s]
[parameters: {'username_1': 'Niklas'}]
(Background on this error at: https://sqlalche.me/e/20/f405)
2024-08-18 17:01:31,411 INFO: Webstats startup [in C:\Users\paul-\PycharmProjects\MagicWebStats\app\__init__.py:56]
2025-09-09 09:36:24,202 INFO: Webstats startup [in D:\PycharmProjects\MagicWebStats\app\__init__.py:71]
2025-09-09 09:37:32,175 INFO: Webstats startup [in D:\PycharmProjects\MagicWebStats\app\__init__.py:71]
2025-09-09 09:44:55,069 INFO: Webstats startup [in D:\PycharmProjects\MagicWebStats\app\__init__.py:71]
