2025-09-09 14:10:06,291 ERROR: Exception on /user/Schlangenbob [GET] [in D:\PycharmProjects\MagicWebStats\.venv\Lib\site-packages\flask\app.py:875]
Traceback (most recent call last):
  File "D:\PycharmProjects\MagicWebStats\.venv\Lib\site-packages\sqlalchemy\engine\base.py", line 1967, in _exec_single_context
    self.dialect.do_execute(
    ~~~~~~~~~~~~~~~~~~~~~~~^
        cursor, str_statement, effective_parameters, context
        ^^^^^^^^^^^^^^^^^^^^^^^^^^^^^^^^^^^^^^^^^^^^^^^^^^^^
    )
    ^
  File "D:\PycharmProjects\MagicWebStats\.venv\Lib\site-packages\sqlalchemy\engine\default.py", line 951, in do_execute
    cursor.execute(statement, parameters)
    ~~~~~~~~~~~~~~^^^^^^^^^^^^^^^^^^^^^^^
psycopg2.errors.InvalidTextRepresentation: invalid input syntax for type integer: "Schlangenbob"
LINE 3: WHERE data_owner."user".spieler = 'Schlangenbob'
                                          ^


The above exception was the direct cause of the following exception:

Traceback (most recent call last):
  File "D:\PycharmProjects\MagicWebStats\.venv\Lib\site-packages\flask\app.py", line 1511, in wsgi_app
    response = self.full_dispatch_request()
  File "D:\PycharmProjects\MagicWebStats\.venv\Lib\site-packages\flask\app.py", line 919, in full_dispatch_request
    rv = self.handle_user_exception(e)
  File "D:\PycharmProjects\MagicWebStats\.venv\Lib\site-packages\flask\app.py", line 917, in full_dispatch_request
    rv = self.dispatch_request()
  File "D:\PycharmProjects\MagicWebStats\.venv\Lib\site-packages\flask\app.py", line 902, in dispatch_request
    return self.ensure_sync(self.view_functions[rule.endpoint])(**view_args)  # type: ignore[no-any-return]
           ~~~~~~~~~~~~~~~~~~~~~~~~~~~~~~~~~~~~~~~~~~~~~~~~~~~~^^^^^^^^^^^^^
  File "D:\PycharmProjects\MagicWebStats\.venv\Lib\site-packages\flask_login\utils.py", line 290, in decorated_view
    return current_app.ensure_sync(func)(*args, **kwargs)
           ~~~~~~~~~~~~~~~~~~~~~~~~~~~~~^^^^^^^^^^^^^^^^^
  File "D:\PycharmProjects\MagicWebStats\app\main\routes.py", line 87, in user
    user = db.first_or_404(sa.select(User).where(User.spieler == spieler))
  File "D:\PycharmProjects\MagicWebStats\.venv\Lib\site-packages\flask_sqlalchemy\extension.py", line 778, in first_or_404
    value = self.session.execute(statement).scalar()
            ~~~~~~~~~~~~~~~~~~~~^^^^^^^^^^^
  File "D:\PycharmProjects\MagicWebStats\.venv\Lib\site-packages\sqlalchemy\orm\scoping.py", line 779, in execute
    return self._proxied.execute(
           ~~~~~~~~~~~~~~~~~~~~~^
        statement,
        ^^^^^^^^^^
    ...<4 lines>...
        _add_event=_add_event,
        ^^^^^^^^^^^^^^^^^^^^^^
    )
    ^
  File "D:\PycharmProjects\MagicWebStats\.venv\Lib\site-packages\sqlalchemy\orm\session.py", line 2365, in execute
    return self._execute_internal(
           ~~~~~~~~~~~~~~~~~~~~~~^
        statement,
        ^^^^^^^^^^
    ...<4 lines>...
        _add_event=_add_event,
        ^^^^^^^^^^^^^^^^^^^^^^
    )
    ^
  File "D:\PycharmProjects\MagicWebStats\.venv\Lib\site-packages\sqlalchemy\orm\session.py", line 2251, in _execute_internal
    result: Result[Any] = compile_state_cls.orm_execute_statement(
                          ~~~~~~~~~~~~~~~~~~~~~~~~~~~~~~~~~~~~~~~^
        self,
        ^^^^^
    ...<4 lines>...
        conn,
        ^^^^^
    )
    ^
  File "D:\PycharmProjects\MagicWebStats\.venv\Lib\site-packages\sqlalchemy\orm\context.py", line 306, in orm_execute_statement
    result = conn.execute(
        statement, params or {}, execution_options=execution_options
    )
  File "D:\PycharmProjects\MagicWebStats\.venv\Lib\site-packages\sqlalchemy\engine\base.py", line 1419, in execute
    return meth(
        self,
        distilled_parameters,
        execution_options or NO_OPTIONS,
    )
  File "D:\PycharmProjects\MagicWebStats\.venv\Lib\site-packages\sqlalchemy\sql\elements.py", line 526, in _execute_on_connection
    return connection._execute_clauseelement(
           ~~~~~~~~~~~~~~~~~~~~~~~~~~~~~~~~~^
        self, distilled_params, execution_options
        ^^^^^^^^^^^^^^^^^^^^^^^^^^^^^^^^^^^^^^^^^
    )
    ^
  File "D:\PycharmProjects\MagicWebStats\.venv\Lib\site-packages\sqlalchemy\engine\base.py", line 1641, in _execute_clauseelement
    ret = self._execute_context(
        dialect,
    ...<8 lines>...
        cache_hit=cache_hit,
    )
  File "D:\PycharmProjects\MagicWebStats\.venv\Lib\site-packages\sqlalchemy\engine\base.py", line 1846, in _execute_context
    return self._exec_single_context(
           ~~~~~~~~~~~~~~~~~~~~~~~~~^
        dialect, context, statement, parameters
        ^^^^^^^^^^^^^^^^^^^^^^^^^^^^^^^^^^^^^^^
    )
    ^
  File "D:\PycharmProjects\MagicWebStats\.venv\Lib\site-packages\sqlalchemy\engine\base.py", line 1986, in _exec_single_context
    self._handle_dbapi_exception(
    ~~~~~~~~~~~~~~~~~~~~~~~~~~~~^
        e, str_statement, effective_parameters, cursor, context
        ^^^^^^^^^^^^^^^^^^^^^^^^^^^^^^^^^^^^^^^^^^^^^^^^^^^^^^^
    )
    ^
  File "D:\PycharmProjects\MagicWebStats\.venv\Lib\site-packages\sqlalchemy\engine\base.py", line 2355, in _handle_dbapi_exception
    raise sqlalchemy_exception.with_traceback(exc_info[2]) from e
  File "D:\PycharmProjects\MagicWebStats\.venv\Lib\site-packages\sqlalchemy\engine\base.py", line 1967, in _exec_single_context
    self.dialect.do_execute(
    ~~~~~~~~~~~~~~~~~~~~~~~^
        cursor, str_statement, effective_parameters, context
        ^^^^^^^^^^^^^^^^^^^^^^^^^^^^^^^^^^^^^^^^^^^^^^^^^^^^
    )
    ^
  File "D:\PycharmProjects\MagicWebStats\.venv\Lib\site-packages\sqlalchemy\engine\default.py", line 951, in do_execute
    cursor.execute(statement, parameters)
    ~~~~~~~~~~~~~~^^^^^^^^^^^^^^^^^^^^^^^
sqlalchemy.exc.DataError: (psycopg2.errors.InvalidTextRepresentation) invalid input syntax for type integer: "Schlangenbob"
LINE 3: WHERE data_owner."user".spieler = 'Schlangenbob'
                                          ^

[SQL: SELECT data_owner."user".id, data_owner."user".username, data_owner."user".email, data_owner."user".password_hash, data_owner."user".spieler, data_owner."user".active, data_owner."user".role 
FROM data_owner."user" 
WHERE data_owner."user".spieler = %(spieler_1)s]
[parameters: {'spieler_1': 'Schlangenbob'}]
(Background on this error at: https://sqlalche.me/e/20/9h9h)
2025-09-09 14:15:37,029 INFO: Webstats startup [in D:\PycharmProjects\MagicWebStats\app\__init__.py:71]
2025-09-09 14:18:26,833 INFO: Webstats startup [in D:\PycharmProjects\MagicWebStats\app\__init__.py:71]
2025-09-09 14:25:48,204 INFO: Webstats startup [in D:\PycharmProjects\MagicWebStats\app\__init__.py:71]
2025-09-09 14:27:52,632 INFO: Webstats startup [in D:\PycharmProjects\MagicWebStats\app\__init__.py:71]
2025-09-09 14:33:45,681 INFO: Webstats startup [in D:\PycharmProjects\MagicWebStats\app\__init__.py:71]
2025-09-09 14:34:01,412 INFO: Webstats startup [in D:\PycharmProjects\MagicWebStats\app\__init__.py:71]
2025-09-09 14:34:23,065 INFO: Webstats startup [in D:\PycharmProjects\MagicWebStats\app\__init__.py:71]
2025-09-09 14:34:34,880 INFO: Webstats startup [in D:\PycharmProjects\MagicWebStats\app\__init__.py:71]
2025-09-09 14:36:41,855 INFO: Webstats startup [in D:\PycharmProjects\MagicWebStats\app\__init__.py:71]
2025-09-09 14:37:15,714 INFO: Webstats startup [in D:\PycharmProjects\MagicWebStats\app\__init__.py:71]
2025-09-09 14:37:32,206 INFO: Webstats startup [in D:\PycharmProjects\MagicWebStats\app\__init__.py:71]
2025-09-09 14:38:46,848 INFO: Webstats startup [in D:\PycharmProjects\MagicWebStats\app\__init__.py:71]
2025-09-09 14:40:58,277 INFO: Webstats startup [in D:\PycharmProjects\MagicWebStats\app\__init__.py:71]
2025-09-09 14:41:40,564 INFO: Webstats startup [in D:\PycharmProjects\MagicWebStats\app\__init__.py:71]
2025-09-09 14:41:58,292 INFO: Webstats startup [in D:\PycharmProjects\MagicWebStats\app\__init__.py:71]
2025-09-09 14:42:20,017 INFO: Webstats startup [in D:\PycharmProjects\MagicWebStats\app\__init__.py:71]
2025-09-09 14:42:53,339 INFO: Webstats startup [in D:\PycharmProjects\MagicWebStats\app\__init__.py:71]
2025-09-09 14:42:56,112 ERROR: Exception on /player/Hauke [GET] [in D:\PycharmProjects\MagicWebStats\.venv\Lib\site-packages\flask\app.py:875]
Traceback (most recent call last):
  File "D:\PycharmProjects\MagicWebStats\.venv\Lib\site-packages\flask\app.py", line 1511, in wsgi_app
    response = self.full_dispatch_request()
  File "D:\PycharmProjects\MagicWebStats\.venv\Lib\site-packages\flask\app.py", line 919, in full_dispatch_request
    rv = self.handle_user_exception(e)
  File "D:\PycharmProjects\MagicWebStats\.venv\Lib\site-packages\flask\app.py", line 917, in full_dispatch_request
    rv = self.dispatch_request()
  File "D:\PycharmProjects\MagicWebStats\.venv\Lib\site-packages\flask\app.py", line 902, in dispatch_request
    return self.ensure_sync(self.view_functions[rule.endpoint])(**view_args)  # type: ignore[no-any-return]
           ~~~~~~~~~~~~~~~~~~~~~~~~~~~~~~~~~~~~~~~~~~~~~~~~~~~~^^^^^^^^^^^^^
  File "D:\PycharmProjects\MagicWebStats\.venv\Lib\site-packages\flask_login\utils.py", line 290, in decorated_view
    return current_app.ensure_sync(func)(*args, **kwargs)
           ~~~~~~~~~~~~~~~~~~~~~~~~~~~~~^^^^^^^^^^^^^^^^^
  File "D:\PycharmProjects\MagicWebStats\app\main\routes.py", line 99, in player
    user = db.first(sa.select(User).where(User.spieler == player.id))
           ^^^^^^^^
  File "D:\PycharmProjects\MagicWebStats\.venv\Lib\site-packages\flask_sqlalchemy\extension.py", line 1008, in __getattr__
    raise AttributeError(name)
AttributeError: first
2025-09-09 14:43:08,575 INFO: Webstats startup [in D:\PycharmProjects\MagicWebStats\app\__init__.py:71]
